Workbook

Sheet 入力シート
B1: 不動産投資 事業計画書 ― 入力シート | K1: ⚠️ Excelでダウンロードしてからご使用ください
B3: 【物件情報】
B4: 購入者名
B5: 事業名称（物件名）
B6: 所在地
B7: 築年 | E7: 年 | G7: 月 | H7: =IF(OR(C7="",D7=""),"",TEXT(IF(C7="西暦",D7,IF(C7="令和",2018+D7,IF(C7="平成",1988+D7,IF(C7="昭和",1925+D7,IF(C7="大正",1911+D7,D7))))),"0")&"年"&IF(F7="","",TEXT(F7,"0")&"月")&"（築"&TEXT(IF(F7="",YEAR(TODAY())-(IF(C7="西暦",D7,IF(C7="令和",2018+D7,IF(C7="平成",1988+D7,IF(C7="昭和",1925+D7,IF(C7="大正",1911+D7,D7)))))),YEAR(TODAY())-(IF(C7="西暦",D7,IF(C7="令和",2018+D7,IF(C7="平成",1988+D7,IF(C7="昭和",1925+D7,IF(C7="大正",1911+D7,D7))))))-IF(MONTH(TODAY())<F7,1,0)),"0")&"年）")
B8: 構造・規模 | F8: ▲規模（例：２階建） | G8: =IF(C8="","",C8&IF(D8="","",D8))
B9: 建蔽率 | D9: %
B10: 容積率 | D10: %
B11: 敷地面積 | D11: ㎡ | E11: =IFERROR(ROUND(VALUE(ASC(C11))/3.30579,2),"") | F11: 坪 (自動)
B12: 延べ床面積 | D12: ㎡ | E12: =IFERROR(ROUND(VALUE(ASC(C12))/3.30579,2),"") | F12: 坪 (自動)
B14: 【購入価格】 ※万円で入力 中古不動産は「土地建物価格」に一括入力でもOK
B15: 土地建物価格 | E15: 万円 | G15: ▲中古不動産など一括金額で入力する場合
B16: 土地価格 | E16: 万円 | G16: ▲内訳が分かる場合に入力
B17: 建物価格 | E17: 万円
B18: 合計取引価格 | C18: =IF(AND(C16="",C17="",C15=""),"",IF(C15<>"",IFERROR(VALUE(ASC(C15))*10000,0),(IFERROR(VALUE(ASC(C16)),0)+IFERROR(VALUE(ASC(C17)),0))*10000)) | E18: 円 | G18: ★土地建物価格 or 土地+建物を自動合算
B20: 【間取り・家賃設定】（最大5タイプ）
B21: タイプ | C21: 戸数 | D21: 実際の家賃（円） | F21: 家賃引き直し（円）
B27: 合計（月額） | D27: =IFERROR(C22*D22,0)+IFERROR(C23*D23,0)+IFERROR(C24*D24,0)+IFERROR(C25*D25,0)+IFERROR(C26*D26,0) -> 0 | F27: 円 | G27: =IFERROR(C22*F22,0)+IFERROR(C23*F23,0)+IFERROR(C24*F24,0)+IFERROR(C25*F25,0)+IFERROR(C26*F26,0) -> 0 | H27: 円
B29: 【諸経費】 黄色=入力セル 緑色=自動計算（上書き可）
B30: 費目 | C30: 実費（円） | F30: 金融機関提出用（円）
B31: 固定資産税・都市計画税 | F31: =C31 -> 0 | H31: ★手持ち用・提出用 共通
B32: 銀行ローン事務手数料等 | F32: =C32 -> 0 | H32: ★手持ち用・提出用 共通
B33: 土地・建物所有権移転登記 | F33: =C33 -> 0 | H33: ★手持ち用・提出用 共通
B34: 抵当権設定登記 | F34: =C34 -> 0 | H34: ★手持ち用・提出用 共通
B35: 司法書士手数料等 | F35: =C35 -> 0 | H35: ★手持ち用・提出用 共通
B36: 契約書印紙代 | F36: =C36 -> 0 | H36: ★手持ち用・提出用 共通
B37: 仲介手数料 | C37: =IF(ISNUMBER(C18),ROUND((C18*0.03+60000)*1.1,0),"") | F37: =IF(ISNUMBER(C18),ROUND((C18*0.03+60000)*1.1,0),"") | H37: ★購入価格×3%+6万×1.1（税込）上書き可
B38: 火災保険料 | F38: =IFERROR(VALUE(ASC(C38))*5,"") | H38: ★1年額入力→提出用(右)は自動で5年分
B39: 不動産取得税 | C39: =IF(ISNUMBER(C18),ROUND(C18*IF(C8="木造",0.015,IF(C8="鉄骨造",0.02,IF(C8="鉄筋コンクリート",0.025,0.03))),0),"") | F39: =IF(ISNUMBER(C18),ROUND(C18*IF(C8="木造",0.015,IF(C8="鉄骨造",0.02,IF(C8="鉄筋コンクリート",0.025,0.03))),0),"") | H39: ★構造別概算（木造1.5%・鉄骨造2%・RC2.5%・未選択3%）高め算出・上書き可
B40: 出資金・その他 | F40: =C40 -> 0 | H40: ★手持ち用・提出用 共通
B41: 諸経費合計 | C41: =SUM(C31:C40) -> 0 | E41: 円 | F41: =SUM(F31:F40) -> 0 | H41: 円
B43: 【融資条件】 ※融資額は万円で入力
B44: 項目 | C44: 実費ケース | F44: 金融機関提出用
B45: 融資額（万円） | E45: 万円 | F45: =C45 -> 0 | H45: 万円 | I45: ★実費と同じ値を自動反映
B46: 融資期間（年） | E46: 年 | F46: =C46 -> 0 | H46: 年 | I46: ★実費と同じ値を自動反映
B47: 金利（年率） | E47: ％ | F47: =C47 -> 0 | H47: ％ | I47: ★例: 4.05 と入力 → 年率4.05%。Googleドライブ経由でも正確に計算
B48: 月間返済額（自動計算・元利均等） | C48: =IF(OR(NOT(ISNUMBER(IFERROR(VALUE(C45)*10000,0))),NOT(ISNUMBER(IFERROR(VALUE(C46),""))),NOT(ISNUMBER(IFERROR(IF(VALUE(C47)>1,VALUE(C47)/100,VALUE(C47)),""))),IFERROR(VALUE(C45)*10000,0)=0),0,ROUND(PMT(IFERROR(IF(VALUE(C47)>1,VALUE(C47)/100,VALUE(C47)),"")/12,IFERROR(VALUE(C46),"")*12,-IFERROR(VALUE(C45)*10000,0)),0)) -> 0 | E48: 円 | F48: =C48 -> 0 | H48: 円
B50: 【ランニングコスト・自己資金】
B51: 月間管理料 | C51: =IFERROR(ROUND(D27*0.05*1.1,0),"") -> 0 | F51: 円/月 | G51: 手持ち5%+税 / 金融機関4%+税で自動計算
...

Sheet 手持ち用
H1: =TODAY() -> 46134
B2: 収益物件事業計画書
B4: =入力シート!C4 -> 0 | C4: 様
B5: 【事業内容】 | F5: 【資金計画】
B6: 事業名称 | C6: =入力シート!C5 -> 0 | F6: 諸経費 | H6: =C31 -> 0 | I6: 円
B7: 住所 | C7: =入力シート!C6 -> 0 | F7: 頭金 | H7: =IFERROR(入力シート!C54*10000,0) -> 0 | I7: 円
B8: 敷地面積 | C8: =IF(ISNUMBER(入力シート!C11),TEXT(入力シート!C11,"0.00")&"㎡ ("&TEXT(入力シート!E11,"0.00")&"坪)","") | F8: 借入金 | H8: =IFERROR(入力シート!C45*10000,0) -> 0 | I8: 円
B9: 築年月 | C9: =入力シート!H7 | F9: 合計 | H9: =SUM(H6:H8) -> 0 | I9: 円
B10: 建蔽率 | C10: =IF(入力シート!C9="","",入力シート!C9&"%")
B11: 容積率 | C11: =IF(入力シート!C10="","",入力シート!C10&"%") | F11: 自己資金 | H11: =SUM(H6:H7) -> 0
B12: 構造・規模 | C12: =入力シート!G8 | F12: 【家賃収入内訳】 | K12: 【家賃引き直し収入内訳】
B13: 延べ床面積 | C13: =IF(ISNUMBER(入力シート!C12),TEXT(入力シート!C12,"0.00")&"㎡ ("&TEXT(入力シート!E12,"0.00")&"坪)","") | F13: タイプ | G13: 戸数 | H13: １戸あたり賃料 | I13: 賃料合計 | K13: タイプ | L13: 戸数 | M13: １戸あたり賃料 | N13: 賃料合計
F14: =入力シート!B22 -> 0 | G14: =入力シート!C22 -> 0 | H14: =入力シート!D22 -> 0 | I14: =IFERROR(G14*H14,0) -> 0 | K14: =入力シート!B22 -> 0 | L14: =入力シート!C22 -> 0 | M14: =入力シート!F22 -> 0 | N14: =IFERROR(L14*M14,0) -> 0
B15: 【事業費】 | F15: =入力シート!B23 -> 0 | G15: =入力シート!C23 -> 0 | H15: =入力シート!D23 -> 0 | I15: =IFERROR(G15*H15,0) -> 0 | K15: =入力シート!B23 -> 0 | L15: =入力シート!C23 -> 0 | M15: =入力シート!F23 -> 0 | N15: =IFERROR(L15*M15,0) -> 0
B16: =IF(OR(入力シート!C16<>"",入力シート!C17<>""),"","土地建物売買価格") -> 土地建物売買価格 | C16: =IF(OR(入力シート!C16<>"",入力シート!C17<>""),"",入力シート!C18) | D16: =IF(OR(入力シート!C16<>"",入力シート!C17<>""),"","円") -> 円 | F16: 合計 | H16: =SUM(I14:I15) -> 0 | I16: 円 | K16: 合計 | M16: =SUM(N14:N15) -> 0 | N16: 円
B17: =IF(入力シート!C15<>"","","土地売買価格") -> 土地売買価格 | C17: =IF(入力シート!C15<>"","",IFERROR(入力シート!C16*10000,"")) -> 0 | D17: =IF(入力シート!C15<>"","","円") -> 円
B18: =IF(入力シート!C15<>"","","建物売買価格") -> 建物売買価格 | C18: =IF(入力シート!C15<>"","",IFERROR(入力シート!C17*10000,"")) -> 0 | D18: =IF(入力シート!C15<>"","","円") -> 円 | F18: 【返済計画】 | K18: 【返済計画】
B19: 事業費合計 | C19: =C16 | D19: 円 | F19: 融資期間 | H19: 融資条件 | I19: 月間返済額 | K19: 融資期間 | M19: 融資条件 | N19: 月間返済額
F20: =IF(ISNUMBER(IFERROR(VALUE(ASC(入力シート!C46)),"")),"銀行融資"&入力シート!C46&"年","") | H20: =IF(ISNUMBER(入力シート!C47),"変動"&TEXT(IF(入力シート!C47>1,入力シート!C47/100,入力シート!C47),"0.00%"),"") | I20: =入力シート!C48 -> 0 | K20: =IF(ISNUMBER(IFERROR(VALUE(ASC(入力シート!C46)),"")),"銀行融資"&入力シート!C46&"年","") | M20: =IF(ISNUMBER(入力シート!C47),"変動"&TEXT(IF(入力シート!C47>1,入力シート!C47/100,入力シート!C47),"0.00%"),"") | N20: =入力シート!C48 -> 0
B21: 【諸経費】 | F21: ◯◯銀行 | K21: ◯◯銀行
B22: 固都税 | C22: =入力シート!C31 -> 0 | D22: 円 | F22: 合計 | H22: =I20 -> 0 | I22: 円 | K22: 合計 | M22: =N20 -> 0 | N22: 円
B23: 銀行手数料・出資金 | C23: =入力シート!C32 -> 0 | D23: 円
B24: 土地・建物登記費用 | C24: =入力シート!C33 -> 0 | D24: 円 | F24: 【収支計画】 | K24: 【収支計画】
B25: 抵当権設定登記 | C25: =入力シート!C34 -> 0 | D25: 円 | F25: 月間収入 | H25: =H16 -> 0 | I25: 円 | K25: 月間収入 | M25: =M16 -> 0 | N25: 円
B26: 司法書士手数料等 | C26: =入力シート!C35 -> 0 | D26: 円 | F26: 月間借入支払 | H26: =H22 -> 0 | I26: 円 | K26: 月間借入支払 | M26: =M22 -> 0 | N26: 円
B27: 契約書印紙代 | C27: =入力シート!C36 -> 0 | D27: 円 | F27: 月間管理料 | H27: =IFERROR(ROUND(H25*0.05*1.1,0),0) -> 0 | I27: 円 | K27: 月間管理料 | M27: =IFERROR(ROUND(M25*0.05*1.1,0),0) -> 0 | N27: 円
B28: 仲介手数料 | C28: =入力シート!C37 | D28: 円 | F28: 巡回清掃 | H28: =入力シート!C52 -> 0 | I28: 円 | K28: 巡回清掃 | M28: =入力シート!C52 -> 0 | N28: 円
B29: 火災保険（１年） | C29: =入力シート!C38 -> 0 | D29: 円 | F29: インターネット | H29: =入力シート!C53 -> 0 | I29: 円 | K29: インターネット | M29: =入力シート!C53 -> 0 | N29: 円
B30: 不動産取得税 | C30: =入力シート!C39 | D30: 円
B31: 諸経費合計 | C31: =SUM(C22:C30) -> 0 | D31: 円 | F31: 月間収支合計 | H31: =H25-SUM(H26:H30) -> 0 | I31: 円 | K31: 月間収支合計 | M31: =M25-SUM(M26:M30) -> 0 | N31: 円
F32: 年間収入 | H32: =H25*12 -> 0 | I32: 円 | K32: 年間収入 | M32: =M25*12 -> 0 | N32: 円
B33: 【総事業費】 | F33: 年間借入支払 | H33: =H26*12 -> 0 | I33: 円 | K33: 年間借入支払 | M33: =M26*12 -> 0 | N33: 円
B34: 事業費合計 | C34: =C19 | D34: 円 | F34: 年間管理料 | H34: =H27*12 -> 0 | I34: 円 | K34: 年間管理料 | M34: =M27*12 -> 0 | N34: 円
B35: 諸経費合計 | C35: =C31 -> 0 | D35: 円 | F35: 固定資産税 | H35: =C22 -> 0 | I35: 円 | K35: 固定資産税 | M35: =C22 -> 0 | N35: 円
B36: 合計 | C36: =C34+C35 -> #VALUE! | D36: 円 | F36: 巡回清掃 | H36: =H28*12 -> 0 | I36: 円 | K36: 巡回清掃 | M36: =M28*12 -> 0 | N36: 円
B37: ※不動産所得税は、取得から半年後に納税通知書が届きます。 | F37: インターネット | H37: =H29*12 -> 0 | I37: 円 | K37: インターネット | M37: =M29*12 -> 0 | N37: 円
F39: 年間収支合計 | H39: =H32-SUM(H33:H38) -> 0 | I39: 円 | K39: 年間収支合計 | M39: =M32-SUM(M33:M38) -> 0 | N39: 円
F40: 月間収支合計 | H40: =H39/12 -> 0 | I40: 円 | K40: 月間収支合計 | M40: =M39/12 -> 0 | N40: 円
F41: 表面利回り | H41: =IFERROR(H32/C19*100,"") | I41: % | K41: 表面利回り | M41: =IFERROR(M32/C19*100,"") | N41: %
F42: NOI | G42: = | H42: =H32-H34-H35-H36 -> 0 | K42: NOI | L42: = | M42: =M32-M34-M35-M36 -> 0
...

Sheet 金融機関提出用
H1: =TODAY() -> 46134
B2: 収益物件事業計画書
B4: =入力シート!C4 -> 0 | C4: 様
B5: 【事業内容】 | F5: 【資金計画】
B6: 事業名称 | C6: =入力シート!C5 -> 0 | F6: 諸経費 | H6: =C31+IFERROR(C19,0)-IFERROR(入力シート!C45*10000,0) -> #VALUE! | I6: 円
B7: 住所 | C7: =入力シート!C6 -> 0 | F7: 借入金 | H7: =IFERROR(入力シート!C45*10000,0) -> 0 | I7: 円
B8: 敷地面積 | C8: =IF(ISNUMBER(入力シート!C11),TEXT(入力シート!C11,"0.00")&"㎡ ("&TEXT(入力シート!E11,"0.00")&"坪)","") | F8: 合計 | H8: =SUM(H6:H7) -> #VALUE! | I8: 円
B9: 築年月 | C9: =入力シート!H7
B10: 建蔽率 | C10: =IF(入力シート!C9="","",入力シート!C9&"%") | F10: 【家賃収入内訳】 | K10: 【家賃引き直し収入内訳】
B11: 容積率 | C11: =IF(入力シート!C10="","",入力シート!C10&"%") | F11: タイプ | G11: 戸数 | H11: １戸あたり賃料 | I11: 賃料合計 | K11: タイプ | L11: 戸数 | M11: １戸あたり賃料 | N11: 賃料合計
B12: 構造・規模 | C12: =入力シート!G8 | F12: =入力シート!B22 -> 0 | G12: =入力シート!C22 -> 0 | H12: =入力シート!D22 -> 0 | I12: =IFERROR(G12*H12,0) -> 0 | K12: =入力シート!B22 -> 0 | L12: =入力シート!C22 -> 0 | M12: =入力シート!F22 -> 0 | N12: =IFERROR(L12*M12,0) -> 0
B13: 延べ床面積 | C13: =IF(ISNUMBER(入力シート!C12),TEXT(入力シート!C12,"0.00")&"㎡ ("&TEXT(入力シート!E12,"0.00")&"坪)","") | F13: =入力シート!B23 -> 0 | G13: =入力シート!C23 -> 0 | H13: =入力シート!D23 -> 0 | I13: =IFERROR(G13*H13,0) -> 0 | K13: =入力シート!B23 -> 0 | L13: =入力シート!C23 -> 0 | M13: =入力シート!F23 -> 0 | N13: =IFERROR(L13*M13,0) -> 0
F14: 合計 | H14: =SUM(I12:I13) -> 0 | I14: 円 | K14: 合計 | M14: =SUM(N12:N13) -> 0 | N14: 円
B15: 【事業費】
B16: =IF(OR(入力シート!C16<>"",入力シート!C17<>""),"","土地建物売買価格") -> 土地建物売買価格 | C16: =IF(OR(入力シート!C16<>"",入力シート!C17<>""),"",入力シート!C18) | D16: =IF(OR(入力シート!C16<>"",入力シート!C17<>""),"","円") -> 円 | F16: 【返済計画】 | K16: 【返済計画】
B17: =IF(入力シート!C15<>"","","土地売買価格") -> 土地売買価格 | C17: =IF(入力シート!C15<>"","",IFERROR(入力シート!C16*10000,"")) -> 0 | D17: =IF(入力シート!C15<>"","","円") -> 円 | F17: 融資期間 | H17: 融資条件 | I17: 月間返済額 | K17: 融資期間 | M17: 融資条件 | N17: 月間返済額
B18: =IF(入力シート!C15<>"","","建物売買価格") -> 建物売買価格 | C18: =IF(入力シート!C15<>"","",IFERROR(入力シート!C17*10000,"")) -> 0 | D18: =IF(入力シート!C15<>"","","円") -> 円 | F18: =IF(ISNUMBER(IFERROR(VALUE(ASC(入力シート!C46)),"")),"銀行融資"&入力シート!C46&"年","") | H18: =IF(ISNUMBER(入力シート!C47),"変動"&TEXT(IF(入力シート!C47>1,入力シート!C47/100,入力シート!C47),"0.00%"),"") | I18: =入力シート!C48 -> 0 | K18: =IF(ISNUMBER(IFERROR(VALUE(ASC(入力シート!C46)),"")),"銀行融資"&入力シート!C46&"年","") | M18: =IF(ISNUMBER(入力シート!C47),"変動"&TEXT(IF(入力シート!C47>1,入力シート!C47/100,入力シート!C47),"0.00%"),"") | N18: =入力シート!C48 -> 0
B19: 事業費合計 | C19: =C16 | D19: 円 | F19: ◯◯銀行 | K19: ◯◯銀行
F20: 合計 | H20: =I18 -> 0 | I20: 円 | K20: 合計 | M20: =N18 -> 0 | N20: 円
B21: 【諸経費】
B22: 固都税 | C22: =入力シート!C31 -> 0 | D22: 円 | F22: 【収支計画】 | K22: 【収支計画】
B23: 銀行手数料・出資金 | C23: =入力シート!C32 -> 0 | D23: 円 | F23: 月間収入 | H23: =H14 -> 0 | I23: 円 | K23: 月間収入 | M23: =M14 -> 0 | N23: 円
B24: 土地・建物登記費用 | C24: =入力シート!C33 -> 0 | D24: 円 | F24: 月間借入支払 | H24: =H20 -> 0 | I24: 円 | K24: 月間借入支払 | M24: =M20 -> 0 | N24: 円
B25: 抵当権設定登記 | C25: =入力シート!C34 -> 0 | D25: 円 | F25: 月間管理料 | H25: =IFERROR(ROUND(H23*0.04*1.1,0),0) -> 0 | I25: 円 | K25: 月間管理料 | M25: =IFERROR(ROUND(M23*0.04*1.1,0),0) -> 0 | N25: 円
B26: 司法書士手数料等 | C26: =入力シート!C35 -> 0 | D26: 円 | F26: 巡回清掃 | H26: =入力シート!C52 -> 0 | I26: 円 | K26: 巡回清掃 | M26: =入力シート!C52 -> 0 | N26: 円
B27: 契約書印紙代 | C27: =入力シート!C36 -> 0 | D27: 円 | F27: インターネット | H27: =入力シート!C53 -> 0 | I27: 円 | K27: インターネット | M27: =入力シート!C53 -> 0 | N27: 円
B28: 仲介手数料 | C28: =入力シート!C37 | D28: 円
B29: 火災保険（５年） | C29: =入力シート!F38 | D29: 円 | F29: 月間収支合計 | H29: =H23-SUM(H24:H28) -> 0 | I29: 円 | K29: 月間収支合計 | M29: =M23-SUM(M24:M28) -> 0 | N29: 円
B30: 不動産取得税 | C30: =入力シート!C39 | D30: 円 | F30: 年間収入 | H30: =H23*12 -> 0 | I30: 円 | K30: 年間収入 | M30: =M23*12 -> 0 | N30: 円
B31: 諸経費合計 | C31: =SUM(C22:C30) -> 0 | D31: 円 | F31: 年間借入支払 | H31: =H24*12 -> 0 | I31: 円 | K31: 年間借入支払 | M31: =M24*12 -> 0 | N31: 円
F32: 年間管理料 | H32: =H25*12 -> 0 | I32: 円 | K32: 年間管理料 | M32: =M25*12 -> 0 | N32: 円
B33: 【総事業費】 | F33: 固定資産税 | H33: =C22 -> 0 | I33: 円 | K33: 固定資産税 | M33: =C22 -> 0 | N33: 円
B34: 事業費合計 | C34: =C19 | D34: 円 | F34: 巡回清掃 | H34: =H26*12 -> 0 | I34: 円 | K34: 巡回清掃 | M34: =M26*12 -> 0 | N34: 円
B35: 諸経費合計 | C35: =C31 -> 0 | D35: 円 | F35: インターネット | H35: =H27*12 -> 0 | I35: 円 | K35: インターネット | M35: =M27*12 -> 0 | N35: 円
B36: 合計 | C36: =C34+C35 -> #VALUE! | D36: 円
B37: ※不動産所得税は、取得から半年後に納税通知書が届きます。 | F37: 年間収支合計 | H37: =H30-SUM(H31:H36) -> 0 | I37: 円 | K37: 年間収支合計 | M37: =M30-SUM(M31:M36) -> 0 | N37: 円
F38: 月間収支合計 | H38: =H37/12 -> 0 | I38: 円 | K38: 月間収支合計 | M38: =M37/12 -> 0 | N38: 円
F39: 表面利回り | H39: =IFERROR(H30/C19*100,"") | I39: % | K39: 表面利回り | M39: =IFERROR(M30/C19*100,"") | N39: %
F40: NOI | G40: = | H40: =H30-H32-H33-H34 -> 0 | K40: NOI | L40: = | M40: =M30-M32-M33-M34 -> 0
F41: FCR | G41: = | H41: =IFERROR(H40/C36*100,"") | K41: FCR | L41: = | M41: =IFERROR(M40/C36*100,"")
...
